import unittest
from fractions import Fraction
from my_sum import sum


class TestSum(unittest.TestCase):
    def test_list_int(self):
        """
        Test that it can sum a list of integers
        """
        data = [1, 2, 3]
        result = sum(data)
        self.assertEqual(result, 6)

    def test_list_fraction(self):
        """
        Test that it can sum a list of fractions
        """
        data = [Fraction(1, 4), Fraction(1, 4), Fraction(2, 5)]
        result = sum(data)
        self.assertEqual(result, 1)

if __name__ == '__main__':
    unittest.main()
    
  # Since this is a failed test result  There were some results that I have noticed. Via the unittest command we can see addiotional information near the bottom of the output. The fail entry via unittest shows us the test method name, the test module,test case and the assertion error.